<?xml version="1.0" encoding="utf-8"?>
<!-- This URDF was automatically created by SolidWorks to URDF Exporter! Originally created by Stephen Brawner (brawner@gmail.com) 
     Commit Version: 1.6.0-4-g7f85cfe  Build Version: 1.6.7995.38578
     For more information, please see http://wiki.ros.org/sw_urdf_exporter -->
<robot
  name="maa_robo">
  <link name="world"/>
	<joint name="base_joint" type="fixed">
		<parent link="world"/>
		<child link="base"/>
		<origin rpy="0 0 0" xyz="0.0 0.0 0.0"/>
	</joint>  
  <link
    name="base">
    <inertial>
      <origin
        xyz="7.68725237632051E-09 -0.000117196159259848 0.0223035726629275"
        rpy="0 0 0" />
      <mass
        value="0.0960374647687132" />
      <inertia
        ixx="0.000137660900428952"
        ixy="-6.84507669729897E-11"
        ixz="4.47337777543071E-12"
        iyy="0.000127992374265441"
        iyz="-3.9139675561881E-06"
        izz="0.000207983638444363" />
    </inertial>
    <visual>
      <origin
        xyz="0 0 0"
        rpy="0 0 0" />
      <geometry>
        <mesh
          filename="package://maa_robo/meshes/base.STL" />
      </geometry>
      <material
        name="">
        <color
          rgba="0.792156862745098 0.819607843137255 0.933333333333333 1" />
      </material>
    </visual>
    <collision>
      <origin
        xyz="0 0 0"
        rpy="0 0 0" />
      <geometry>
        <mesh
          filename="package://maa_robo/meshes/base.STL" />
      </geometry>
    </collision>
  </link>
  <link
    name="waist">
    <inertial>
      <origin
        xyz="0.00137198894444329 0.00643461749228535 0.0172894151625552"
        rpy="0 0 0" />
      <mass
        value="0.0680383082919642" />
      <inertia
        ixx="4.50177278884508E-05"
        ixy="-6.41756883366727E-07"
        ixz="-6.242745329176E-06"
        iyy="5.81331875484946E-05"
        iyz="-5.17766096312002E-06"
        izz="5.46763891539818E-05" />
    </inertial>
    <visual>
      <origin
        xyz="0 0 0"
        rpy="0 0 0" />
      <geometry>
        <mesh
          filename="package://maa_robo/meshes/waist.STL" />
      </geometry>
      <material
        name="">
        <color
          rgba="0.792156862745098 0.819607843137255 0.933333333333333 1" />
      </material>
    </visual>
    <collision>
      <origin
        xyz="0 0 0"
        rpy="0 0 0" />
      <geometry>
        <mesh
          filename="package://maa_robo/meshes/waist.STL" />
      </geometry>
    </collision>
  </link>
  <joint
    name="base_waist"
    type="revolute">
    <origin
      xyz="0 0 0.056"
      rpy="0 0 0" />
    <parent
      link="base" />
    <child
      link="waist" />
    <axis
      xyz="0 0 1" />
    <limit
      lower="-1.57"
      upper="1.57"
      effort="100"
      velocity="10" />
  </joint>
  <link
    name="l1">
    <inertial>
      <origin
        xyz="-0.000130106407256289 -0.00596879502387518 0.0585900559342434"
        rpy="0 0 0" />
      <mass
        value="0.0643926898356934" />
      <inertia
        ixx="0.000107038199873111"
        ixy="-2.38430401316143E-10"
        ixz="-1.65474705517812E-09"
        iyy="0.000111844791276673"
        iyz="-2.39605334002934E-07"
        izz="9.10999555994351E-06" />
    </inertial>
    <visual>
      <origin
        xyz="0 0 0"
        rpy="0 0 0" />
      <geometry>
        <mesh
          filename="package://maa_robo/meshes/l1.STL" />
      </geometry>
      <material
        name="">
        <color
          rgba="0 0.254901960784314 0.92156862745098 1" />
      </material>
    </visual>
    <collision>
      <origin
        xyz="0 0 0"
        rpy="0 0 0" />
      <geometry>
        <mesh
          filename="package://maa_robo/meshes/l1.STL" />
      </geometry>
    </collision>
  </link>
  <joint
    name="waist_l1"
    type="revolute">
    <origin
      xyz="0.0139185063019886 0 0.0402764801759331"
      rpy="0 0 0" />
    <parent
      link="waist" />
    <child
      link="l1" />
    <axis
      xyz="0 -1 0" />
    <limit
      lower="-1.57"
      upper="1.57"
      effort="100"
      velocity="10" />
  </joint>
  <link
    name="l2">
    <inertial>
      <origin
        xyz="-2.78467675450256E-05 0.0124088533653967 0.0392853069242696"
        rpy="0 0 0" />
      <mass
        value="0.0502682806615447" />
      <inertia
        ixx="5.46008375858883E-05"
        ixy="5.45448123955486E-11"
        ixz="6.95836541632603E-08"
        iyy="5.81489722176159E-05"
        iyz="-2.87532410943136E-07"
        izz="9.28677087867067E-06" />
    </inertial>
    <visual>
      <origin
        xyz="0 0 0"
        rpy="0 0 0" />
      <geometry>
        <mesh
          filename="package://maa_robo/meshes/l2.STL" />
      </geometry>
      <material
        name="">
        <color
          rgba="0.792156862745098 0.819607843137255 0.933333333333333 1" />
      </material>
    </visual>
    <collision>
      <origin
        xyz="0 0 0"
        rpy="0 0 0" />
      <geometry>
        <mesh
          filename="package://maa_robo/meshes/l2.STL" />
      </geometry>
    </collision>
  </link>
  <joint
    name="l1_l2"
    type="revolute">
    <origin
      xyz="0 0 0.12"
      rpy="0 0 0" />
    <parent
      link="l1" />
    <child
      link="l2" />
    <axis
      xyz="0 -1 0" />
    <limit
      lower="-1.57"
      upper="1.57"
      effort="100"
      velocity="10" />
  </joint>
  <link
    name="wrist">
    <inertial>
      <origin
        xyz="-0.00504588853149997 -0.00526464962477612 0.0178410779408339"
        rpy="0 0 0" />
      <mass
        value="0.0164993958869603" />
      <inertia
        ixx="3.91219989876637E-06"
        ixy="3.98661484984632E-09"
        ixz="-1.15840362114129E-08"
        iyy="5.02234105520811E-06"
        iyz="5.75786773493404E-07"
        izz="2.61243222808143E-06" />
    </inertial>
    <visual>
      <origin
        xyz="0 0 0"
        rpy="0 0 0" />
      <geometry>
        <mesh
          filename="package://maa_robo/meshes/wrist.STL" />
      </geometry>
      <material
        name="">
        <color
          rgba="0.792156862745098 0.819607843137255 0.933333333333333 1" />
      </material>
    </visual>
    <collision>
      <origin
        xyz="0 0 0"
        rpy="0 0 0" />
      <geometry>
        <mesh
          filename="package://maa_robo/meshes/wrist.STL" />
      </geometry>
    </collision>
  </link>
  <joint
    name="l2_wrist"
    type="revolute">
    <origin
      xyz="0.00510000000056034 0.0125 0.0915999999999688"
      rpy="0 0 0" />
    <parent
      link="l2" />
    <child
      link="wrist" />
    <axis
      xyz="0 0 1" />
    <limit
      lower="-1.57"
      upper="1.57"
      effort="100"
      velocity="10" />
  </joint>
  <link
    name="gbase">
    <inertial>
      <origin
        xyz="-0.00581676000557846 -0.0133733926702193 0.023551132424968"
        rpy="0 0 0" />
      <mass
        value="0.0157214039263101" />
      <inertia
        ixx="8.11576233259366E-06"
        ixy="3.50347396819704E-07"
        ixz="1.36413018972221E-06"
        iyy="7.24744386013897E-06"
        iyz="-1.4285481948546E-06"
        izz="2.56045826172451E-06" />
    </inertial>
    <visual>
      <origin
        xyz="0 0 0"
        rpy="0 0 0" />
      <geometry>
        <mesh
          filename="package://maa_robo/meshes/gbase.STL" />
      </geometry>
      <material
        name="">
        <color
          rgba="0.792156862745098 0.819607843137255 0.933333333333333 1" />
      </material>
    </visual>
    <collision>
      <origin
        xyz="0 0 0"
        rpy="0 0 0" />
      <geometry>
        <mesh
          filename="package://maa_robo/meshes/gbase.STL" />
      </geometry>
    </collision>
  </link>
  <joint
    name="wrist_gbase"
    type="revolute">
    <origin
      xyz="-0.00499999999982817 0 0.0280999999985383"
      rpy="0 0 0" />
    <parent
      link="wrist" />
    <child
      link="gbase" />
    <axis
      xyz="0 -1 0" />
    <limit
      lower="-1.57"
      upper="1.57"
      effort="100"
      velocity="10" />
  </joint>
  <link
    name="g1">
    <inertial>
      <origin
        xyz="-0.00199999999683453 -0.000161235027441656 0.00569538349082349"
        rpy="0 0 0" />
      <mass
        value="0.00256585966934385" />
      <inertia
        ixx="4.46162551545415E-07"
        ixy="-1.20130144310868E-18"
        ixz="-9.67479293293822E-18"
        iyy="3.60124622567171E-07"
        iyz="-3.07394390301934E-08"
        izz="9.28802214298281E-08" />
    </inertial>
    <visual>
      <origin
        xyz="0 0 0"
        rpy="0 0 0" />
      <geometry>
        <mesh
          filename="package://maa_robo/meshes/g1.STL" />
      </geometry>
      <material
        name="">
        <color
          rgba="0.792156862745098 0.819607843137255 0.933333333333333 1" />
      </material>
    </visual>
    <collision>
      <origin
        xyz="0 0 0"
        rpy="0 0 0" />
      <geometry>
        <mesh
          filename="package://maa_robo/meshes/g1.STL" />
      </geometry>
    </collision>
  </link>
  <joint
    name="gbase_g1"
    type="revolute">
    <origin
      xyz="-0.0174999999994603 0.00255000000000001 0.0380000000001071"
      rpy="0 0 0" />
    <parent
      link="gbase" />
    <child
      link="g1" />
    <axis
      xyz="-1 0 0" />
    <limit
      lower="0"
      upper="1.2"
      effort="100"
      velocity="10" />
  </joint>
  <link
    name="e1">
    <inertial>
      <origin
        xyz="0.00824997740859393 -0.00641733113152839 0.0265001380598517"
        rpy="0 0 0" />
      <mass
        value="0.00539747144897691" />
      <inertia
        ixx="1.71391043056579E-06"
        ixy="-1.39870677399308E-11"
        ixz="1.08370914619553E-12"
        iyy="1.64752389372081E-06"
        iyz="2.52446907551089E-07"
        izz="1.31381061776948E-07" />
    </inertial>
    <visual>
      <origin
        xyz="0 0 0"
        rpy="0 0 0" />
      <geometry>
        <mesh
          filename="package://maa_robo/meshes/e1.STL" />
      </geometry>
      <material
        name="">
        <color
          rgba="0.792156862745098 0.819607843137255 0.933333333333333 1" />
      </material>
    </visual>
    <collision>
      <origin
        xyz="0 0 0"
        rpy="0 0 0" />
      <geometry>
        <mesh
          filename="package://maa_robo/meshes/e1.STL" />
      </geometry>
    </collision>
  </link>
  <joint
    name="g1_e1"
    type="continuous">
    <origin
      xyz="-0.00399999999556312 0.00239679273381367 0.0306564493153397"
      rpy="0 0 0" />
    <parent
      link="g1" />
    <child
      link="e1" />
    <axis
      xyz="1 0 0" />
    <limit
      lower="-1.57"
      upper="1.57"
      effort="100"
      velocity="10" />
    <mimic
      joint="gbase_g1"
      multiplier="1"
      offset="0" />
  </joint>
  <link
    name="g2">
    <inertial>
      <origin
        xyz="-0.00199999999585265 0.000286426960356828 0.00560381935948695"
        rpy="0 0 0" />
      <mass
        value="0.00264161328462974" />
      <inertia
        ixx="4.47239667493299E-07"
        ixy="2.99284283016667E-19"
        ixz="-9.49077022501083E-18"
        iyy="3.62323596177571E-07"
        iyz="2.46355432043757E-08"
        izz="9.19603734080734E-08" />
    </inertial>
    <visual>
      <origin
        xyz="0 0 0"
        rpy="0 0 0" />
      <geometry>
        <mesh
          filename="package://maa_robo/meshes/g2.STL" />
      </geometry>
      <material
        name="">
        <color
          rgba="0.792156862745098 0.819607843137255 0.933333333333333 1" />
      </material>
    </visual>
    <collision>
      <origin
        xyz="0 0 0"
        rpy="0 0 0" />
      <geometry>
        <mesh
          filename="package://maa_robo/meshes/g2.STL" />
      </geometry>
    </collision>
  </link>
  <joint
    name="gbase_g2"
    type="continuous">
    <origin
      xyz="-0.0175000000005596 -0.024350000000004 0.0380000000000114"
      rpy="0 0 0" />
    <parent
      link="gbase" />
    <child
      link="g2" />
    <axis
      xyz="-1 0 0" />
    <limit
      lower="-1.57"
      upper="1.57"
      effort="100"
      velocity="10" />
    <mimic
      joint="gbase_g1"
      multiplier="-1"
      offset="0" />
  </joint>
  <link
    name="e2">
    <inertial>
      <origin
        xyz="0.00825002259168447 0.00627581448406113 0.0265340084729163"
        rpy="0 0 0" />
      <mass
        value="0.00539747142778352" />
      <inertia
        ixx="1.71391041628828E-06"
        ixy="-1.39809990450883E-11"
        ixz="-1.1586024557424E-12"
        iyy="1.65017517269228E-06"
        iyz="-2.44341343971673E-07"
        izz="1.28729768374852E-07" />
    </inertial>
    <visual>
      <origin
        xyz="0 0 0"
        rpy="0 0 0" />
      <geometry>
        <mesh
          filename="package://maa_robo/meshes/e2.STL" />
      </geometry>
      <material
        name="">
        <color
          rgba="0.792156862745098 0.819607843137255 0.933333333333333 1" />
      </material>
    </visual>
    <collision>
      <origin
        xyz="0 0 0"
        rpy="0 0 0" />
      <geometry>
        <mesh
          filename="package://maa_robo/meshes/e2.STL" />
      </geometry>
    </collision>
  </link>
  <joint
    name="g2_e2"
    type="continuous">
    <origin
      xyz="-0.00399999999461456 -0.00173398551481527 0.030701071549261"
      rpy="0 0 0" />
    <parent
      link="g2" />
    <child
      link="e2" />
    <axis
      xyz="-1 0 0" />
    <limit
      lower="-1.57"
      upper="1.57"
      effort="100"
      velocity="10" />
    <mimic
      joint="gbase_g1"
      multiplier="1"
      offset="0" />
  </joint>
  <link
    name="s1">
    <inertial>
      <origin
        xyz="-0.00199999999495828 0.00132555466767997 0.0154432154954331"
        rpy="0 0 0" />
      <mass
        value="0.000798762413184692" />
      <inertia
        ixx="1.04424225659604E-07"
        ixy="-2.38140373087695E-19"
        ixz="-2.73949753414788E-18"
        iyy="1.02195591529061E-07"
        iyz="-8.46007494223569E-09"
        izz="4.35866723236837E-09" />
    </inertial>
    <visual>
      <origin
        xyz="0 0 0"
        rpy="0 0 0" />
      <geometry>
        <mesh
          filename="package://maa_robo/meshes/s1.STL" />
      </geometry>
      <material
        name="">
        <color
          rgba="0.792156862745098 0.819607843137255 0.933333333333333 1" />
      </material>
    </visual>
    <collision>
      <origin
        xyz="0 0 0"
        rpy="0 0 0" />
      <geometry>
        <mesh
          filename="package://maa_robo/meshes/s1.STL" />
      </geometry>
    </collision>
  </link>
  <joint
    name="gbase_s1"
    type="continuous">
    <origin
      xyz="-0.0175000000005648 -0.00635000000000067 0.0580000000000249"
      rpy="0 0 0" />
    <parent
      link="gbase" />
    <child
      link="s1" />
    <axis
      xyz="-1 0 0" />
    <limit
      lower="-1.57"
      upper="1.57"
      effort="100"
      velocity="10" />
    <mimic
      joint="gbase_g1"
      multiplier="1"
      offset="0" />
  </joint>
  <link
    name="s2">
    <inertial>
      <origin
        xyz="-0.00200000000129294 -0.000598194042163623 0.0154884525982406"
        rpy="0 0 0" />
      <mass
        value="0.000798762413184691" />
      <inertia
        ixx="1.04424225659604E-07"
        ixy="9.6313402214335E-20"
        ixz="-2.70212808107845E-18"
        iyy="1.02773869920507E-07"
        iyz="3.82903159087908E-09"
        izz="3.78038884092272E-09" />
    </inertial>
    <visual>
      <origin
        xyz="0 0 0"
        rpy="0 0 0" />
      <geometry>
        <mesh
          filename="package://maa_robo/meshes/s2.STL" />
      </geometry>
      <material
        name="">
        <color
          rgba="0.792156862745098 0.819607843137255 0.933333333333333 1" />
      </material>
    </visual>
    <collision>
      <origin
        xyz="0 0 0"
        rpy="0 0 0" />
      <geometry>
        <mesh
          filename="package://maa_robo/meshes/s2.STL" />
      </geometry>
    </collision>
  </link>
  <joint
    name="gbase_s2"
    type="continuous">
    <origin
      xyz="-0.0175 -0.01635 0.058"
      rpy="0 0 0" />
    <parent
      link="gbase" />
    <child
      link="s2" />
    <axis
      xyz="-1 0 0" />
    <limit
      lower="-1.57"
      upper="1.57"
      effort="100"
      velocity="10" />
    <mimic
      joint="gbase_g1"
      multiplier="-1"
      offset="0" />
  </joint>
  <link
    name="s3">
    <inertial>
      <origin
        xyz="-0.00200000000128649 0.00132555466771932 0.0154432154949791"
        rpy="0 0 0" />
      <mass
        value="0.000798762413184691" />
      <inertia
        ixx="1.04424225659603E-07"
        ixy="-2.38133840302571E-19"
        ixz="-2.73947547103814E-18"
        iyy="1.02195591529061E-07"
        iyz="-8.46007494223565E-09"
        izz="4.35866723236836E-09" />
    </inertial>
    <visual>
      <origin
        xyz="0 0 0"
        rpy="0 0 0" />
      <geometry>
        <mesh
          filename="package://maa_robo/meshes/s3.STL" />
      </geometry>
      <material
        name="">
        <color
          rgba="0.792156862745098 0.819607843137255 0.933333333333333 1" />
      </material>
    </visual>
    <collision>
      <origin
        xyz="0 0 0"
        rpy="0 0 0" />
      <geometry>
        <mesh
          filename="package://maa_robo/meshes/s3.STL" />
      </geometry>
    </collision>
  </link>
  <joint
    name="gbase_s3"
    type="continuous">
    <origin
      xyz="-0.005 -0.00635 0.058"
      rpy="0 0 0" />
    <parent
      link="gbase" />
    <child
      link="s3" />
    <axis
      xyz="-1 0 0" />
    <limit
      lower="-1.57"
      upper="1.57"
      effort="100"
      velocity="10" />
    <mimic
      joint="gbase_g1"
      multiplier="1"
      offset="0" />
  </joint>
  <link
    name="s4">
    <inertial>
      <origin
        xyz="-0.00200000000129294 -0.000598194042156296 0.0154884525982762"
        rpy="0 0 0" />
      <mass
        value="0.000798762413184692" />
      <inertia
        ixx="1.04424225659604E-07"
        ixy="9.63110016081955E-20"
        ixz="-2.70211063966424E-18"
        iyy="1.02773869920507E-07"
        iyz="3.82903159087907E-09"
        izz="3.78038884092272E-09" />
    </inertial>
    <visual>
      <origin
        xyz="0 0 0"
        rpy="0 0 0" />
      <geometry>
        <mesh
          filename="package://maa_robo/meshes/s4.STL" />
      </geometry>
      <material
        name="">
        <color
          rgba="0.792156862745098 0.819607843137255 0.933333333333333 1" />
      </material>
    </visual>
    <collision>
      <origin
        xyz="0 0 0"
        rpy="0 0 0" />
      <geometry>
        <mesh
          filename="package://maa_robo/meshes/s4.STL" />
      </geometry>
    </collision>
  </link>
  <joint
    name="gbase_s4"
    type="continuous">
    <origin
      xyz="-0.00499999999428026 -0.0163500000000442 0.0580000000001468"
      rpy="0 0 0" />
    <parent
      link="gbase" />
    <child
      link="s4" />
    <axis
      xyz="-1 0 0" />
    <limit
      lower="-1.57"
      upper="1.57"
      effort="100"
      velocity="10" />
    <mimic
      joint="gbase_g1"
      multiplier="-1"
      offset="0" />
  </joint>
  <transmission name="waist_trans">
	<type>transmission_interface/SimpleTransmission</type>
	<joint name="base_waist">
	
	<hardwareInterface>hardware_interface/PositionJointInterface</hardwareInterface>
	</joint>
	<actuator name="waist_motor">
	
	<hardwareInterface>hardware_interface/PositionJointInterface</hardwareInterface>
		<mechanicalReduction>1</mechanicalReduction>
	</actuator>
  </transmission>
  <transmission name="l1_trans">
	<type>transmission_interface/SimpleTransmission</type>
	<joint name="waist_l1">
	
	<hardwareInterface>hardware_interface/PositionJointInterface</hardwareInterface>
	</joint>
	<actuator name="l1_motor">
	
	<hardwareInterface>hardware_interface/PositionJointInterface</hardwareInterface>
		<mechanicalReduction>1</mechanicalReduction>
	</actuator>
  </transmission>
  <transmission name="l2_trans">
	<type>transmission_interface/SimpleTransmission</type>
	<joint name="l1_l2">
	
	<hardwareInterface>hardware_interface/PositionJointInterface</hardwareInterface>
	</joint>
	<actuator name="l2_motor">
	
	<hardwareInterface>hardware_interface/PositionJointInterface</hardwareInterface>
		<mechanicalReduction>1</mechanicalReduction>
	</actuator>
  </transmission>
  <transmission name="wrist_trans">
	<type>transmission_interface/SimpleTransmission</type>
	<joint name="l2_wrist">
	
	<hardwareInterface>hardware_interface/PositionJointInterface</hardwareInterface>
	</joint>
	<actuator name="wrist_motor">
	
	<hardwareInterface>hardware_interface/PositionJointInterface</hardwareInterface>
		<mechanicalReduction>1</mechanicalReduction>
	</actuator>
  </transmission>
  <transmission name="gbase_trans">
	<type>transmission_interface/SimpleTransmission</type>
	<joint name="wrist_gbase">
	
	<hardwareInterface>hardware_interface/PositionJointInterface</hardwareInterface>
	</joint>
	<actuator name="gbase_motor">
	
	<hardwareInterface>hardware_interface/PositionJointInterface</hardwareInterface>
		<mechanicalReduction>1</mechanicalReduction>
	</actuator>
  </transmission>
  <transmission name="g1_trans">
	<type>transmission_interface/SimpleTransmission</type>
	<joint name="gbase_g1">
	
	<hardwareInterface>hardware_interface/PositionJointInterface</hardwareInterface>
	</joint>
	<actuator name="g1_motor">
	
	<hardwareInterface>hardware_interface/PositionJointInterface</hardwareInterface>
		<mechanicalReduction>1</mechanicalReduction>
	</actuator>
  </transmission>
  <transmission name="e1_trans">
	<type>transmission_interface/SimpleTransmission</type>
	<joint name="g1_e1">
	
	<hardwareInterface>hardware_interface/PositionJointInterface</hardwareInterface>
	</joint>
	<actuator name="e1_motor">
	
	<hardwareInterface>hardware_interface/PositionJointInterface</hardwareInterface>
		<mechanicalReduction>1</mechanicalReduction>
	</actuator>
  </transmission>
  <transmission name="g2_trans">
	<type>transmission_interface/SimpleTransmission</type>
	<joint name="gbase_g2">
	
	<hardwareInterface>hardware_interface/PositionJointInterface</hardwareInterface>
	</joint>
	<actuator name="g2_motor">
	
	<hardwareInterface>hardware_interface/PositionJointInterface</hardwareInterface>
		<mechanicalReduction>1</mechanicalReduction>
	</actuator>
  </transmission>
  <transmission name="e2_trans">
	<type>transmission_interface/SimpleTransmission</type>
	<joint name="g2_e2">
	
	<hardwareInterface>hardware_interface/PositionJointInterface</hardwareInterface>
	</joint>
	<actuator name="e2_motor">
	
	<hardwareInterface>hardware_interface/PositionJointInterface</hardwareInterface>
		<mechanicalReduction>1</mechanicalReduction>
	</actuator>
  </transmission>
  <transmission name="s1_trans">
	<type>transmission_interface/SimpleTransmission</type>
	<joint name="gbase_s1">
	
	<hardwareInterface>hardware_interface/PositionJointInterface</hardwareInterface>
	</joint>
	<actuator name="s1_motor">
	
	<hardwareInterface>hardware_interface/PositionJointInterface</hardwareInterface>
		<mechanicalReduction>1</mechanicalReduction>
	</actuator>
  </transmission>
  <transmission name="s2_trans">
	<type>transmission_interface/SimpleTransmission</type>
	<joint name="gbase_s2">
	
	<hardwareInterface>hardware_interface/PositionJointInterface</hardwareInterface>
	</joint>
	<actuator name="s2_motor">
	
	<hardwareInterface>hardware_interface/PositionJointInterface</hardwareInterface>
		<mechanicalReduction>1</mechanicalReduction>
	</actuator>
  </transmission>
  <transmission name="s3_trans">
	<type>transmission_interface/SimpleTransmission</type>
	<joint name="gbase_s3">
	
	<hardwareInterface>hardware_interface/PositionJointInterface</hardwareInterface>
	</joint>
	<actuator name="s3_motor">
	
	<hardwareInterface>hardware_interface/PositionJointInterface</hardwareInterface>
		<mechanicalReduction>1</mechanicalReduction>
	</actuator>
  </transmission>
  <transmission name="s4_trans">
	<type>transmission_interface/SimpleTransmission</type>
	<joint name="gbase_s4">
	
	<hardwareInterface>hardware_interface/PositionJointInterface</hardwareInterface>
	</joint>
	<actuator name="s4_motor">
	
	<hardwareInterface>hardware_interface/PositionJointInterface</hardwareInterface>
		<mechanicalReduction>1</mechanicalReduction>
	</actuator>
  </transmission>
  
  <gazebo>
	<plugin name="control" filename="libgazebo_ros_control.so">
		<robotNamespace>/</robotNamespace>
	</plugin>
  </gazebo>
  
  <gazebo reference="waist">
	<selfCollide>true</selfCollide>
  </gazebo>
  <gazebo reference="l1">
	<selfCollide>true</selfCollide>
  </gazebo>
  <gazebo reference="l2">
	<selfCollide>true</selfCollide>
  </gazebo>
  <gazebo reference="wrist">
	<selfCollide>true</selfCollide>
  </gazebo>
  <gazebo reference="gbase">
	<selfCollide>true</selfCollide>
  </gazebo>
  <gazebo reference="g1">
	<selfCollide>true</selfCollide>
  </gazebo>
  <gazebo reference="e1">
	<selfCollide>true</selfCollide>
  </gazebo>
  <gazebo reference="g2">
	<selfCollide>true</selfCollide>
  </gazebo>
  <gazebo reference="e2">
	<selfCollide>true</selfCollide>
  </gazebo>
  <gazebo reference="s1">
	<selfCollide>true</selfCollide>
  </gazebo>
  <gazebo reference="s2">
	<selfCollide>true</selfCollide>
  </gazebo>
  <gazebo reference="s3">
	<selfCollide>true</selfCollide>
  </gazebo>
  <gazebo reference="s4">
	<selfCollide>true</selfCollide>
  </gazebo>  
</robot>
